Workbook
Name AvCnPrmtr1: #REF!
Name AvCnPrmtr1: #REF!
Name AvCnPrmtr2: #REF!
Name AvCnPrmtr2: #REF!
Name d: #REF!
Name d: #REF!
Name f: #REF!
Name f: #REF!
Name old: #REF!
Name old: #REF!
Name PCube_Well_1996: #REF!
Name PCube_Well_1996: #REF!
Name PCube_Well_1997: #REF!
Name PCube_Well_1997: #REF!
Name PCube_Well_1998: #REF!
Name PCube_Well_1998: #REF!
Name PCube_Well_1999: #REF!
Name PCube_Well_1999: #REF!
Name PCube_Well_2000: #REF!
Name PCube_Well_2000: #REF!
Name PCube_Well_2001: #REF!
Name PCube_Well_2001: #REF!
Name PCube_Well_2002: #REF!
Name PCube_Well_2002: #REF!
Name PCube_Well_2003: #REF!
Name PCube_Well_2003: #REF!
Name PCube_Well_2004: #REF!
Name PCube_Well_2004: #REF!
Name PCube_Well_2005: #REF!
Name PCube_Well_2005: #REF!
Name PCube_Well_2006: #REF!
Name PCube_Well_2006: #REF!
Name PCube_Well_2007: #REF!
Name PCube_Well_2007: #REF!
Name PCube_Well_2008: #REF!
Name PCube_Well_2008: #REF!
Name Production_by_Grouping_by_Month02_HI: #REF!
Name Production_by_Grouping_by_Month02_HI: #REF!
Name Production_by_Grouping_by_Month02_Ref: #REF!
Name Production_by_Grouping_by_Month02_Ref: #REF!
Name Query1: #REF!
Name Query1: #REF!
Name Tbl_6_4_TotCan: #REF!
Name Tbl_6_4_TotCan: #REF!
Name wwww: #REF!
Name wwww: #REF!
Name wwwww: #REF!
Name wwwww: #REF!
Name x: #REF!
Name x: #REF!
Name zz_FcstDL3: #REF!
Name zz_FcstDL3: #REF!
Name zz_GasOilSplit3: [1]zz_GasOilSplit3!$A$1:$M$2071
Name zzz_Tbl_6_1_DL: #REF!
Name zzz_Tbl_6_1_DL: #REF!

Sheet ES.10
A1: Figure ES.10: Illustrative Export Capacity from Pipelines and Structural Rail, vs. Total Crude Oil Supply Available from the Western Canadian Sedimentary Basin (WCSB), Evolving and Current Policies Scenarios
A2: Mb/d
A3: Table of Contents
B6: Total Supply Available for Export - Evolving Policies | C6: Total Supply Available for Export - Current Policies | D6: Total Pipeline and Structural Rail Capacity
A7: 2010 | B7: 2300.0368 | C7: 2300.0368 | D7: 2914.9241 | E7: =B7/D7 -> 0.78905548
A8: 2011 | B8: 2539.7542 | C8: 2539.7542 | D8: 3307.6263 | E8: =B8/D8 -> 0.76784799
A9: 2012 | B9: 2849.2916 | C9: 2849.2916 | D9: 3388.8681 | E9: =B9/D9 -> 0.84077971
A10: 2013 | B10: 3086.4659 | C10: 3086.4659 | D10: 3458.9628 | E10: =B10/D10 -> 0.89230968
A11: 2014 | B11: 3343.9966 | C11: 3343.9966 | D11: 3613.5409 | E11: =B11/D11 -> 0.92540715
A12: 2015 | B12: 3536.9547 | C12: 3536.9547 | D12: 3862.2633 | E12: =B12/D12 -> 0.91577254
A13: 2016 | B13: 3602.8553 | C13: 3602.8553 | D13: 4107.3528 | E13: =B13/D13 -> 0.8771721
A14: 2017 | B14: 3892.784 | C14: 3892.784 | D14: 4207.1355 | E14: =B14/D14 -> 0.92528133
A15: 2018 | B15: 4269.488 | C15: 4269.488 | D15: 4183.3888 | E15: =B15/D15 -> 1.0205812
A16: 2019 | B16: 4250.5046 | C16: 4250.5046 | D16: 4257.7167 | E16: =B16/D16 -> 0.99830612
A17: 2020 | B17: 3975.1369 | C17: 3975.1369 | D17: 4280.286 | E17: =B17/D17 -> 0.92870824
A18: 2021 | B18: 4251.4143 | C18: 4214.7132 | D18: 4403.6677 | E18: =B18/D18 -> 0.96542578
... A47: 2050 | B47: 4283.4646 | C47: 5833.6655 | D47: 5261.8445 | E47: =B47/D47 -> 0.81406141

Sheet 2020_mods
A1: Figure 10.7 - Canadian Oil Export Pipeline Capacity and Oil Exports
O2: =(560-50+87)/6.2929 -> 94.86882
A3: Year | B3: Enbridge Mainline | C3: Express | D3: Trans Mountain | E3: Keystone | F3: Rangeland/Milk River | G3: Implied Rail | H3: Total existing | I3: NEB 2023 Total | J3: Diff | K3: Keystone XL | L3: Northern Gateway | M3: Energy East | N3: CAPP 2014 Offtake | O3: NEB 2016 Offtake | P3: TM Ref Prod | Q3: Western Refinery Runs Net Burnaby + NWR | R3: CAPP 2018 Supply Raw | S3: CAPP 2018 Offtake | T3: CAPP 2014 Supply Raw | U3: Enbridge Bakken Volumes | V3: CAPP 2019 Supply Raw | W3: CER 2019 Supply Available | X3: CER 2019 Mod | Y3: CER 2020 Reference | Z3: CER 2020 Evolving | AA3: CER 2021 Evolving | AB3: CER 2021 Current | AC3: CER 2021 Total Capacity | AD3: S_P_2025
A4: 2010 | B4: 397 | C4: 32 | D4: 47 | E4: 35.6 | F4: 22.384476 | G4: 0 | H4: =SUM(B4:G4)-G4 -> 533.98448 | I4: =AC4/6.2981 -> 462.82595 | J4: =I4-H4 -> -71.158529 | N4: =T4/6.2929-Q4+U4 -> 355.86518 | O4: 357 | P4: 6.5 | Q4: 69 | R4: 2667.8101 | S4: =R4/6.2929-Q4+U4 -> 354.9397 | T4: 2673.6341 | U4: 0 | V4: 2667.8101 | W4: 2196.7771 | X4: =W4/6.2929 -> 349.0882 | Y4: 349.17283 | Z4: 349.17283 | AA4: 2300.0368 | AB4: 2300.0368 | AC4: 2914.9241
A5: 2011 | B5: 397 | C5: 28 | D5: 36 | E5: 80.6 | F5: 22.384476 | G5: 0 | H5: =SUM(B5:G5)-G5 -> 563.98448 | I5: =AC5/6.2981 -> 525.17843 | J5: =I5-H5 -> -38.806045 | N5: =T5/6.2929-Q5+U5 -> 388.59903 | O5: 388 | P5: 6.5 | Q5: 76 | R5: 2899.9742 | S5: =R5/6.2929-Q5+U5 -> 384.83272 | T5: 2923.6752 | U5: 0 | V5: 2899.9742 | W5: 2419.0307 | X5: =W5/6.2929 -> 384.40635 | Y5: 384.4659 | Z5: 384.4659 | AA5: 2539.7542 | AB5: 2539.7542 | AC5: 3307.6263
A6: 2012 | B6: 397 | C6: 30 | D6: 44 | E6: 83.5 | F6: 22.384476 | G6: 0 | H6: =SUM(B6:G6)-G6 -> 576.88448 | I6: =AC6/6.2981 -> 538.07785 | J6: =I6-H6 -> -38.806622 | K6: 66 | N6: =T6/6.2929-Q6+U6 -> 435.84037 | O6: 441 | P6: 6.5 | Q6: 79 | R6: 3222.4606 | S6: =R6/6.2929-Q6+U6 -> 433.07878 | T6: 3239.839 | U6: 0 | V6: 3222.4606 | W6: 2710.8171 | X6: =W6/6.2929 -> 430.7739 | Y6: 430.79504 | Z6: 430.79504 | AA6: 2849.2916 | AB6: 2849.2916 | AC6: 3388.8681 | AD6: 3100
A7: 2013 | B7: 397 | C7: 32 | D7: 39 | E7: 82.8 | F7: 22.384476 | G7: 11 | H7: =SUM(B7:G7)-G7 -> 573.18448 | I7: =AC7/6.2981 -> 549.20734 | J7: =I7-H7 -> -23.977133 | K7: 132 | N7: =T7/6.2929-Q7+U7 -> 477.79989 | O7: 465 | P7: 6.5 | Q7: 79 | R7: 3450.6709 | S7: =R7/6.2929-Q7+U7 -> 474.34351 | T7: 3472.4215 | U7: 5 | V7: 3450.6709 | W7: 2942.6771 | X7: =W7/6.2929 -> 467.61861 | Y7: 467.88835 | Z7: 467.88835 | AA7: 3086.4659 | AB7: 3086.4659 | AC7: 3458.9628 | AD7: 3300
A8: 2014 | B8: 416 | C8: 31 | D8: 50 | E8: 87.2 | F8: 22.384476 | G8: 25 | H8: =SUM(B8:G8)-G8 -> 606.58448 | I8: =AC8/6.2981 -> 573.75096 | J8: =I8-H8 -> -32.83352 | K8: 132 | N8: =T8/6.2929-Q8+U8 -> 508.8681 | O8: 514 | P8: 6.5 | Q8: 83 | R8: 3799.8119 | S8: =R8/6.2929-Q8+U8 -> 530.82524 | T8: 3661.6378 | U8: 10 | V8: 3799.8119 | W8: 3188.1333 | X8: =W8/6.2929 -> 506.62387 | Y8: 506.6833 | Z8: 506.6833 | AA8: 3343.9966 | AB8: 3343.9966 | AC8: 3613.5409 | AD8: 3500
A9: 2015 | B9: 453 | C9: =280/6.2929 -> 44.494589 | D9: 45 | E9: 93.1 | F9: 22.384476 | G9: 23 | H9: =SUM(B9:G9)-G9 -> 657.97907 | I9: =AC9/6.2981 -> 613.24261 | J9: =I9-H9 -> -44.736451 | K9: 132 | N9: =T9/6.2929-Q9+U9 -> 557.30065 | O9: 544 | P9: 6.5 | Q9: 83 | R9: 3981.7356 | S9: =R9/6.2929-Q9+U9 -> 564.73461 | T9: 3934.9545 | U9: 15 | V9: 3981.7356 | W9: 3394.3287 | X9: =W9/6.2929 -> 539.39022 | Y9: 541.27707 | Z9: 541.27707 | AA9: 3536.9547 | AB9: 3536.9547 | AC9: 3862.2633 | AD9: 3650
A10: 2016 | B10: 453 | C10: =280/6.2929 -> 44.494589 | D10: 46 | E10: 95.1 | F10: 22.384476 | G10: 52 | H10: =SUM(B10:G10)-G10 -> 660.97907 | I10: =AC10/6.2981 -> 652.15745 | J10: =I10-H10 -> -8.8216155 | K10: 132 | N10: =T10/6.2929-Q10+U10 -> 619.72999 | O10: 597 | P10: 6.5 | Q10: 79.3 | R10: 3910.2335 | S10: =R10/6.2929-Q10+U10 -> 565.07226 | T10: 4254.1891 | U10: 23 | V10: 3910.2335 | W10: 3472.4554 | X10: =W10/6.2929 -> 551.80527 | Y10: 553.55108 | Z10: 553.55108 | AA10: 3602.8553 | AB10: 3602.8553 | AC10: 4107.3528 | AD10: 3800
A11: 2017 | B11: 453 | C11: =280/6.2929 -> 44.494589 | D11: 49 | E11: 92.6 | F11: 22.384476 | G11: 83 | H11: =SUM(B11:G11)-G11 -> 661.47907 | I11: =AC11/6.2981 -> 668.00075 | J11: =I11-H11 -> 6.521688 | K11: 132 | N11: =T11/6.2929-Q11+U11 -> 652.48306 | O11: 628 | P11: 6.5 | Q11: 78 | R11: 4194.4091 | S11: =R11/6.2929-Q11+U11 -> 611.53038 | T11: 4452.1202 | U11: 23 | V11: 4194.4091 | W11: 3776.0591 | X11: =W11/6.2929 -> 600.05071 | Y11: 602.20114 | Z11: 602.20114 | AA11: 3892.784 | AB11: 3892.784 | AC11: 4207.1355 | AD11: 3975
A12: 2018 | B12: 453 | C12: =280/6.2929 -> 44.494589 | D12: 50 | E12: 93.7 | F12: 22.384476 | G12: 69 | H12: =SUM(B12:G12)-G12 -> 663.57907 | I12: =AC12/6.2981 -> 664.23029 | J12: =I12-H12 -> 0.65122836 | K12: 132 | L12: 42 | N12: =T12/6.2929-Q12+U12 -> 685.48454 | O12: 630 | P12: 6.5 | Q12: 78 | R12: 4540.1731 | S12: =R12/6.2929-Q12+U12 -> 666.47549 | T12: 4659.7951 | U12: 23 | V12: 4657.382 | W12: 4146.9923 | X12: =W12/6.2929 -> 658.99543 | Y12: 663.13768 | Z12: 663.13768 | AA12: 4269.488 | AB12: 4269.488 | AC12: 4183.3888 | AD12: 4150
A13: 2019 | B13: 460 | C13: =280/6.2929 -> 44.494589 | D13: 49 | E13: 91.2 | F13: 22.384476 | G13: 17 | H13: =SUM(B13:G13)-G13 -> 667.07907 | I13: =AC13/6.2981 -> 676.03193 | J13: =I13-H13 -> 8.952864 | K13: 132 | L13: 83 | N13: =T13/6.2929-Q13+U13 -> 715.76882 | O13: 644 | P13: 6.5 | Q13: =Q12+50/6.2929 -> 85.945462 | R13: 4776.4755 | S13: =R13/6.2929-Q13+U13 -> 696.08067 | T13: 4900.3711 | U13: 23 | V13: 4801.8176 | W13: 4207.3856 | X13: =W13/6.2929 -> 668.59247 | Y13: 665.00419 | Z13: 664.97623 | AA13: 4250.5046 | AB13: 4250.5046 | AC13: 4257.7167 | AD13: 4025
A14: 2020 | B14: 460 | C14: =310/6.2929 -> 49.261867 | D14: 53 | E14: 95 | F14: 22.384476 | G14: 18 | H14: =SUM(B14:G14)-G14 -> 679.64634 | I14: =AC14/6.2981 -> 679.61545 | J14: =I14-H14 -> -0.030896769 | K14: 132 | L14: 83 | N14: =T14/6.2929-Q14+U14 -> 754.76525 | O14: 645 | P14: 6.5 | Q14: =95 -> 95 | R14: 4943.5522 | S14: =R14/6.2929-Q14+U14 -> 713.57616 | T14: 5202.751 | U14: 23 | V14: 5003.5315 | W14: 4399.7022 | X14: =W14/6.2929 -> 699.15336 | Y14: 578.78969 | Z14: 580.14844 | AA14: 3975.1369 | AB14: 3975.1369 | AC14: 4280.286 | AD14: 3900
A15: 2021 | B15: 512 | C15: =310/6.2929 -> 49.261867 | D15: 33.3 | E15: 99.7 | F15: 22.384476 | G15: 15 | H15: =SUM(B15:G15)-G15 -> 716.64634 | I15: =AC15/6.2981 -> 699.20575 | J15: =I15-H15 -> -17.440592 | K15: 132 | L15: 83 | M15: 87 | N15: =T15/6.2929-Q15+U15 -> 799.68896 | O15: 646 | P15: 6.5 | Q15: =Q14 -> 95 | R15: 5016.895 | S15: =R15/6.2929-Q15+U15 -> 725.23101 | T15: 5485.4515 | U15: 23 | V15: 5093.3401 | W15: 4599.5395 | X15: =W15/6.2929 -> 730.90936 | Y15: 658.34191 | Z15: 642.46025 | AA15: 4251.4143 | AB15: 4214.7132 | AC15: 4403.6677 | AD15: 4150
A16: 2022 | B16: 512 | C16: =310/6.2929 -> 49.261867 | D16: 55 | E16: 98.9 | F16: 22.384476 | G16: 17 | H16: =SUM(B16:G16)-G16 -> 737.54634 | I16: =AC16/6.2981 -> 751.37918 | J16: =I16-H16 -> 13.832838 | K16: 132 | L16: 83 | M16: 175 | N16: =T16/6.2929-Q16+U16 -> 834.89043 | O16: 649 | P16: 6.5 | Q16: =Q15 -> 95 | R16: 5094.1414 | S16: =R16/6.2929-Q16+U16 -> 737.50618 | T16: 5706.9708 | U16: 23 | V16: 5226.2319 | W16: 4673.9683 | X16: =W16/6.2929 -> 742.73678 | Y16: 700.41372 | Z16: 685.55336 | AA16: 4483.1248 | AB16: 4451.4105 | AC16: 4732.2612 | AD16: 4400
A17: 2023 | B17: 512 | C17: =310/6.2929 -> 49.261867 | D17: 51 | E17: 98.9 | F17: 22.384476 | G17: 23 | H17: =SUM(B17:G17)-G17 -> 733.54634 | I17: =AC17/6.2981 -> 829.77584 | J17: =I17-H17 -> 96.229497 | K17: 132 | L17: 83 | M17: 175 | N17: =T17/6.2929-Q17+U17 -> 868.29611 | O17: 654 | P17: 6.5 | Q17: =Q16 -> 95 | R17: 5164.2718 | S17: =R17/6.2929-Q17+U17 -> 748.65054 | T17: 5917.1894 | U17: 23 | V17: 5297.1994 | W17: 4762.5459 | X17: =W17/6.2929 -> 756.81258 | Y17: 717.12147 | Z17: 693.92846 | AA17: 4646.7004 | AB17: 4629.0314 | AC17: 5226.0112 | AD17: 4625
A18: 2024 | B18: 512 | C18: =310/6.2929 -> 49.261867 | D18: 143 | E18: 98.9 | F18: 22.384476 | G18: 33 | H18: =SUM(B18:G18)-G18 -> 825.54634 | I18: =AC18/6.2981 -> 835.46539 | J18: =I18-H18 -> 9.9190435 | K18: 132 | L18: 83 | M18: 175 | N18: =T18/6.2929-Q18+U18 -> 911.19436 | O18: 665 | P18: 6.5 | Q18: =Q17 -> 95 | R18: 5199.7327 | S18: =R18/6.2929-Q18+U18 -> 754.2856 | T18: 6187.1438 | U18: 23 | V18: 5383.5318 | W18: 4923.9182 | X18: =W18/6.2929 -> 782.45613 | Y18: 735.98657 | Z18: 702.50471 | AA18: 4914.7502 | AB18: 4928.1539 | AC18: 5261.8445 | AD18: 4850
A19: 2025 | B19: 512 | C19: =310/6.2929 -> 49.261867 | D19: 142 | E19: 101.6 | F19: 22.384476 | G19: 43 | H19: =SUM(B19:G19)-G19 -> 827.24634 | I19: =AC19/6.2981 -> 835.46539 | J19: =I19-H19 -> 8.2190435 | K19: 132 | L19: 83 | M19: 175 | N19: =T19/6.2929-Q19+U19 -> 946.24914 | O19: 674 | P19: 6.5 | Q19: =Q18 -> 95 | R19: 5251.6139 | S19: =R19/6.2929-Q19+U19 -> 762.53002 | T19: 6407.74 | U19: 23 | V19: 5471.6786 | W19: 5116.7624 | X19: =W19/6.2929 -> 813.10086 | Y19: 759.13165 | Z19: 713.88309 | AA19: 4975.0394 | AB19: 5012.9632 | AC19: 5261.8445 | AD19: 5050
A20: 2026 | B20: 512 | C20: =310/6.2929 -> 49.261867 | D20: 142 | E20: 103.51283 | F20: 22.384476 | G20: 64 | H20: =SUM(B20:G20)-G20 -> 829.15917 | I20: =AC20/6.2981 -> 835.46539 | J20: =I20-H20 -> 6.3062152 | K20: 132 | L20: 83 | M20: 175 | N20: =T20/6.2929-Q20+U20 -> 986.61179 | O20: 695 | P20: 6.5 | Q20: =Q19 -> 95 | R20: 5322.2347 | S20: =R20/6.2929-Q20+U20 -> 773.75231 | T20: 6661.7381 | U20: 23 | V20: 5581.2002 | W20: 5273.0193 | X20: =W20/6.2929 -> 837.93153 | Y20: 780.09805 | Z20: 719.96336 | AA20: 4992.4163 | AB20: 5072.5549 | AC20: 5261.8445 | AD20: 5050
A21: 2027 | B21: 512 | C21: =310/6.2929 -> 49.261867 | D21: 142 | E21: 103.51283 | F21: 22.384476 | G21: 80 | H21: =SUM(B21:G21)-G21 -> 829.15917 | I21: =AC21/6.2981 -> 835.46539 | J21: =I21-H21 -> 6.3062152 | K21: 132 | L21: 83 | M21: 175 | N21: =T21/6.2929-Q21+U21 -> 1017.1728 | O21: 712 | P21: 6.5 | Q21: =Q20 -> 95 | R21: 5375.2681 | S21: =R21/6.2929-Q21+U21 -> 782.1798 | T21: 6854.0552 | U21: 23 | V21: 5665.8024 | W21: 5383.1211 | X21: =W21/6.2929 -> 855.42772 | Y21: 806.75426 | Z21: 731.45865 | AA21: 5062.2174 | AB21: 5186.2466 | AC21: 5261.8445 | AD21: 5050
A22: 2028 | B22: 512 | C22: =310/6.2929 -> 49.261867 | D22: 142 | E22: 103.51283 | F22: 22.384476 | G22: 94 | H22: =SUM(B22:G22)-G22 -> 829.15917 | I22: =AC22/6.2981 -> 835.46539 | J22: =I22-H22 -> 6.3062152 | K22: 131.89467 | L22: 83.427355 | M22: 174.80017 | N22: =T22/6.2929-Q22+U22 -> 1049.644 | O22: 725 | P22: 6.5 | Q22: =Q21 -> 95 | R22: 5433.9916 | S22: =R22/6.2929-Q22+U22 -> 791.51151 | T22: 7058.3937 | U22: 23 | V22: 5752.9744 | W22: 5414.0937 | X22: =W22/6.2929 -> 860.34955 | Y22: 825.15607 | Z22: 740.62329 | AA22: 5052.8459 | AB22: 5254.2923 | AC22: 5261.8445 | AD22: 5050
A23: 2029 | B23: 512 | C23: =310/6.2929 -> 49.261867 | D23: 142 | E23: 103.51283 | F23: 22.384476 | G23: 106 | H23: =SUM(B23:G23)-G23 -> 829.15917 | I23: =AC23/6.2981 -> 835.46539 | J23: =I23-H23 -> 6.3062152 | K23: 131.89467 | L23: 83.427355 | M23: 174.80017 | N23: =T23/6.2929-Q23+U23 -> 1077.5188 | O23: 737 | P23: 6.5 | Q23: =Q22 -> 95 | R23: 5564.8383 | S23: =R23/6.2929-Q23+U23 -> 812.30426 | T23: 7233.807 | U23: 23 | V23: 5782.697 | W23: 5497.8603 | X23: =W23/6.2929 -> 873.66084 | Y23: 840.97653 | Z23: 748.37602 | AA23: 5059.932 | AB23: 5339.9486 | AC23: 5261.8445 | AD23: 5042
A24: 2030 | B24: 512 | C24: =310/6.2929 -> 49.261867 | D24: 142 | E24: 103.51283 | F24: 22.384476 | G24: 119 | H24: =SUM(B24:G24)-G24 -> 829.15917 | I24: =AC24/6.2981 -> 835.46539 | J24: =I24-H24 -> 6.3062152 | K24: 131.89467 | L24: 83.427355 | M24: 174.80017 | N24: =T24/6.2929-Q24+U24 -> 1112.7314 | O24: 750 | P24: 6.5 | Q24: =Q23 -> 95 | R24: 5688.3823 | S24: =R24/6.2929-Q24+U24 -> 831.93654 | T24: 7455.3963 | U24: 23 | V24: 5866.7319 | W24: 5614.8826 | X24: =W24/6.2929 -> 892.25676 | Y24: 853.91554 | Z24: 754.07162 | AA24: 5028.7605 | AB24: 5293.2017 | AC24: 5261.8445 | AD24: 5033
A25: 2031 | B25: 512 | C25: =310/6.2929 -> 49.261867 | D25: 142 | E25: 103.51283 | F25: 22.384476 | G25: 130 | H25: =SUM(B25:G25)-G25 -> 829.15917 | I25: =AC25/6.2981 -> 835.46539 | J25: =I25-H25 -> 6.3062152 | K25: 131.89467 | L25: 83.427355 | M25: 174.80017 | O25: 762 | P25: 6.5 | Q25: =Q24 -> 95 | R25: 5807.7552 | S25: =R25/6.2929-Q25+U25 -> 850.906 | U25: 23 | V25: 5949.4698 | W25: 5741.2155 | X25: =W25/6.2929 -> 912.33223 | Y25: 868.03837 | Z25: 760.15432 | AA25: 4989.5713 | AB25: 5419.3603 | AC25: 5261.8445 | AD25: 5025
A26: 2032 | B26: 512 | C26: =310/6.2929 -> 49.261867 | D26: 142 | E26: 103.51283 | F26: 22.384476 | G26: 139 | H26: =SUM(B26:G26)-G26 -> 829.15917 | I26: =AC26/6.2981 -> 835.46539 | J26: =I26-H26 -> 6.3062152 | K26: 131.89467 | L26: 83.427355 | M26: 174.80017 | O26: 770 | P26: 6.5 | Q26: =Q25 -> 95 | R26: 5892.2313 | S26: =R26/6.2929-Q26+U26 -> 864.33005 | U26: 23 | V26: 6023.0604 | W26: 5802.2369 | X26: =W26/6.2929 -> 922.02909 | Y26: 874.21243 | Z26: 760.92373 | AA26: 4947.929 | AB26: 5515.1098 | AC26: 5261.8445 | AD26: 5017
A27: 2033 | B27: 512 | C27: =310/6.2929 -> 49.261867 | D27: 142 | E27: 103.51283 | F27: 22.384476 | G27: 147 | H27: =SUM(B27:G27)-G27 -> 829.15917 | I27: =AC27/6.2981 -> 835.46539 | J27: =I27-H27 -> 6.3062152 | K27: 131.89467 | L27: 83.427355 | M27: 174.80017 | O27: 778 | P27: 6.5 | Q27: =Q26 -> 95 | R27: 6000.892 | S27: =R27/6.2929-Q27+U27 -> 881.59724 | U27: 23 | V27: 6139.2517 | W27: 5934.2647 | X27: =W27/6.2929 -> 943.00954 | Y27: 895.96606 | Z27: 773.35432 | AA27: 4984.7982 | AB27: 5657.4376 | AC27: 5261.8445 | AD27: 5008
A28: 2034 | B28: 512 | C28: =310/6.2929 -> 49.261867 | D28: 142 | E28: 103.51283 | F28: 22.384476 | G28: 155 | H28: =SUM(B28:G28)-G28 -> 829.15917 | I28: =AC28/6.2981 -> 835.46539 | J28: =I28-H28 -> 6.3062152 | K28: 131.89467 | L28: 83.427355 | M28: 174.80017 | O28: 787 | P28: 6.5 | Q28: =Q27 -> 95 | R28: 6092.9251 | S28: =R28/6.2929-Q28+U28 -> 896.22214 | U28: 23 | V28: 6254.0171 | W28: 5994.6236 | X28: =W28/6.2929 -> 952.60113 | Y28: 911.82228 | Z28: 782.81205 | AA28: 4974.1781 | AB28: 5728.7985 | AC28: 5261.8445 | AD28: 5000
A29: 2035 | B29: 512 | C29: =310/6.2929 -> 49.261867 | D29: 142 | E29: 103.51283 | F29: 22.384476 | G29: 163 | H29: =SUM(B29:G29)-G29 -> 829.15917 | I29: =AC29/6.2981 -> 835.46539 | J29: =I29-H29 -> 6.3062152 | K29: 131.89467 | L29: 83.427355 | M29: 174.80017 | O29: 794 | P29: 6.5 | Q29: =Q28 -> 95 | R29: 6156.7118 | S29: =R29/6.2929-Q29+U29 -> 906.35844 | U29: 23 | V29: 6335.601 | W29: 6001.8983 | X29: =W29/6.2929 -> 953.75714 | Y29: 916.56947 | Z29: 783.35164 | AA29: 4910.832 | AB29: 5755.2658 | AC29: 5261.8445 | AD29: 4950
A30: 2036 | B30: 512 | C30: =310/6.2929 -> 49.261867 | D30: 142 | E30: 103.51283 | F30: 22.384476 | G30: 168 | H30: =SUM(B30:G30)-G30 -> 829.15917 | I30: =AC30/6.2981 -> 835.46539 | J30: =I30-H30 -> 6.3062152 | K30: 131.89467 | L30: 83.427355 | M30: 174.80017 | O30: 799 | P30: 6.5 | Q30: =Q29 -> 95 | U30: 23 | W30: 5996.0388 | X30: =W30/6.2929 -> 952.82601 | Y30: 916.34071 | Z30: 774.98482 | AA30: 4832.4943 | AB30: 5750.3596 | AC30: 5261.8445 | AD30: 4900
A31: 2037 | B31: 512 | C31: =310/6.2929 -> 49.261867 | D31: 142 | E31: 103.51283 | F31: 22.384476 | G31: 172 | H31: =SUM(B31:G31)-G31 -> 829.15917 | I31: =AC31/6.2981 -> 835.46539 | J31: =I31-H31 -> 6.3062152 | K31: 131.89467 | L31: 83.427355 | M31: 174.80017 | O31: 804 | P31: 6.5 | Q31: =Q30 -> 95 | U31: 23 | W31: 6056.2272 | X31: =W31/6.2929 -> 962.3905 | Y31: 928.20503 | Z31: 773.50345 | AA31: 4783.4358 | AB31: 5762.0364 | AC31: 5261.8445 | AD31: 4850
A32: 2038 | B32: 512 | C32: =310/6.2929 -> 49.261867 | D32: 142 | E32: 103.51283 | F32: 22.384476 | G32: 178 | H32: =SUM(B32:G32)-G32 -> 829.15917 | I32: =AC32/6.2981 -> 835.46539 | J32: =I32-H32 -> 6.3062152 | K32: 131.89467 | L32: 83.427355 | M32: 174.80017 | O32: 810 | P32: 6.5 | Q32: =Q31 -> 95 | U32: 23 | W32: 6083.2094 | X32: =W32/6.2929 -> 966.67823 | Y32: 932.79349 | Z32: 767.7116 | AA32: 4722.0224 | AB32: 5769.5935 | AC32: 5261.8445 | AD32: 4800
A33: 2039 | B33: 512 | C33: =310/6.2929 -> 49.261867 | D33: 142 | E33: 103.51283 | F33: 22.384476 | G33: 184 | H33: =SUM(B33:G33)-G33 -> 829.15917 | I33: =AC33/6.2981 -> 835.46539 | J33: =I33-H33 -> 6.3062152 | K33: 131.89467 | L33: 83.427355 | M33: 174.80017 | O33: 815 | P33: 6.5 | Q33: =Q32 -> 95 | U33: 23 | W33: 6140.8698 | X33: =W33/6.2929 -> 975.841 | Y33: 941.85963 | Z33: 768.65402 | AA33: 4670.9564 | AB33: 5768.7674 | AC33: 5261.8445 | AD33: 4750
A34: 2040 | B34: 512 | C34: =310/6.2929 -> 49.261867 | D34: 142 | E34: 103.51283 | F34: 22.384476 | G34: 187 | H34: =SUM(B34:G34)-G34 -> 829.15917 | I34: =AC34/6.2981 -> 835.46539 | J34: =I34-H34 -> 6.3062152 | K34: 131.89467 | L34: 83.427355 | M34: 174.80017 | O34: 818 | P34: 6.5 | Q34: =Q33 -> 95 | U34: 23 | W34: 6171.5513 | X34: =W34/6.2929 -> 980.71657 | Y34: 940.72079 | Z34: 762.84175 | AA34: 4615.7385 | AB34: 5751.5012 | AC34: 5261.8445 | AD34: 4700
A35: 2041 | B35: 512 | C35: =310/6.2929 -> 49.261867 | D35: 142 | E35: 103.51283 | F35: 22.384476 | G35: 187 | H35: =SUM(B35:G35)-G35 -> 829.15917 | I35: =AC35/6.2981 -> 835.46539 | J35: =I35-H35 -> 6.3062152 | K35: 131.89467 | L35: 83.427355 | M35: 174.80017 | O35: 818 | P35: 6.5 | Q35: =Q34 -> 95 | U35: 23 | Y35: 944.30106 | Z35: 760.54081 | AA35: 4590.0173 | AB35: 5778.7783 | AC35: 5261.8445 | AD35: 4675
A36: 2042 | B36: 512 | C36: =310/6.2929 -> 49.261867 | D36: 142 | E36: 103.51283 | F36: 22.384476 | G36: 187 | H36: =SUM(B36:G36)-G36 -> 829.15917 | I36: =AC36/6.2981 -> 835.46539 | J36: =I36-H36 -> 6.3062152 | K36: 131.89467 | L36: 83.427355 | M36: 174.80017 | O36: 818 | P36: 6.5 | Q36: =Q35 -> 95 | U36: 23 | Y36: 948.17994 | Z36: 756.3087 | AA36: 4553.7748 | AB36: 5780.9967 | AC36: 5261.8445 | AD36: 4650
A37: 2043 | B37: 512 | C37: =310/6.2929 -> 49.261867 | D37: 142 | E37: 103.51283 | F37: 22.384476 | G37: 187 | H37: =SUM(B37:G37)-G37 -> 829.15917 | I37: =AC37/6.2981 -> 835.46539 | J37: =I37-H37 -> 6.3062152 | K37: 131.89467 | L37: 83.427355 | M37: 174.80017 | O37: 818 | P37: 6.5 | Q37: =Q36 -> 95 | U37: 23 | Y37: 953.39959 | Z37: 754.02165 | AA37: 4518.0741 | AB37: 5783.4576 | AC37: 5261.8445 | AD37: 4625
A38: 2044 | B38: 512 | C38: =310/6.2929 -> 49.261867 | D38: 142 | E38: 103.51283 | F38: 22.384476 | G38: 187 | H38: =SUM(B38:G38)-G38 -> 829.15917 | I38: =AC38/6.2981 -> 835.46539 | J38: =I38-H38 -> 6.3062152 | K38: 131.89467 | L38: 83.427355 | M38: 174.80017 | O38: 818 | P38: 6.5 | Q38: =Q37 -> 95 | U38: 23 | Y38: 957.16081 | Z38: 751.58523 | AA38: 4469.9245 | AB38: 5772.394 | AC38: 5261.8445 | AD38: 4600
A39: 2045 | B39: 512 | C39: =310/6.2929 -> 49.261867 | D39: 142 | E39: 103.51283 | F39: 22.384476 | G39: 187 | H39: =SUM(B39:G39)-G39 -> 829.15917 | I39: =AC39/6.2981 -> 835.46539 | J39: =I39-H39 -> 6.3062152 | K39: 131.89467 | L39: 83.427355 | M39: 174.80017 | O39: 818 | P39: 6.5 | Q39: =Q38 -> 95 | U39: 23 | Y39: 963.44485 | Z39: 749.42954 | AA39: 4448.5205 | AB39: 5801.2829 | AC39: 5261.8445 | AD39: 4575
A40: 2046 | B40: 512 | C40: =310/6.2929 -> 49.261867 | D40: 142 | E40: 103.51283 | F40: 22.384476 | G40: 187 | H40: =SUM(B40:G40)-G40 -> 829.15917 | I40: =AC40/6.2981 -> 835.46539 | J40: =I40-H40 -> 6.3062152 | K40: 131.89467 | L40: 83.427355 | M40: 174.80017 | O40: 818 | P40: 6.5 | Q40: =Q39 -> 95 | U40: 23 | Y40: 967.98263 | Z40: 744.97725 | AA40: 4414.4893 | AB40: 5827.9577 | AC40: 5261.8445 | AD40: 4550
...

Sheet Sheet1
A1: Table R.1: Pipeline Capacity Assumptions for Figure R.14
A3: Name | B3: Takeaway Capacity (current or timing as noted) (Mb/d) | C3: cubic meters | D3: Notes
A4: Enbridge Mainline | B4: 3207 | C4: =B4/6.2898 -> 509.87313 | D4: Stated capacity includes the fully completed Line 3 Replacement Project which adds 370 Mb/d of capacity to the Enbridge Mainline in late 2021.
A5: Keystone | B5: 586 | C5: =B5/6.2898 -> 93.166714 | D5: Capacity held fixed over the projection period. The cancelled Keystone XL project is not included in Figure R.14.
A6: Trans Mountain | B6: 300 | C6: =B6/6.2898 -> 47.69627 | D6: Capacity is held fixed over the projection period. This capacity approximates the crude oil portion of capacity, by removing 50 Mb/d from the full capacity of Trans Mountain (350 Mb/d) to accommodate transportation of 50 mb/d of RPPs on the pipeline.
A7: Trans Mountain Expansion | B7: 540 | C7: =B7/6.2898 -> 85.853286 | D7: The Trans Mountain Expansion Project adds capacity starting in December 2022, and increases to full capacity by the spring of 2023. As with the existing Trans Mountain system, full capacity of the Trans Mountain Expansion (590 Mb/d) is reduced to accommodate transportation of 50 Mb/d of RPPs.
A8: Express | B8: 310 | C8: =B8/6.2898 -> 49.286146 | D8: Capacity held fixed over the projection period.
A9: Milk River | B9: 97 | C9: =B9/6.2898 -> 15.421794 | D9: Capacity held fixed over the projection period.
A10: Aurora/Rangeland | B10: 44 | C10: =B10/6.2898 -> 6.995453 | D10: Capacity held fixed over the projection period.
A11: Structural Rail | B11: 120 | C11: =B11/6.2898 -> 19.078508 | D11: Capacity held fixed over the projection period.
A12: Capacity Increases to Existing Pipelines | B12: 58 | C12: =B12/6.2898 -> 9.2212789 | D12: Includes announced optimizations to boost the capacity of existing pipelines. The capacity increases are reflected in 2021 to 2023.
A13: Total | B13: 5 262

Sheet 10.7
A1: Figure 10.7 - Canadian Oil Export Pipeline Capacity and Oil Exports
G2: =(560-50+87)/6.2929 -> 94.86882
B3: Enbridge Mainline | C3: Express | D3: Trans Mountain | E3: Keystone | F3: Rangeland/Milk River | G3: NEB 2016 Offtake | H3: Implied Rail | I3: Enbridge Expansions | J3: CAPP 2018 Offtake | K3: Keystone XL | L3: Trans Mountain Expansion | M3: Northern Gateway | N3: Energy East | O3: CAPP 2014 Offtake | P3: TM Ref Prod | Q3: Western Refinery Runs Net Burnaby + NWR | R3: 2018 CAPP Supply Raw | S3: 2014 CAPP Supply Raw | T3: Enbridge Bakken Volumes | U3: CAPP 2019 Supply Raw | V3: CER 2019 Supply Available | W3: CER 2019 Mod | X3: CER 2020 Reference | Y3: CER 2020 Evolving
A4: 2010 | B4: 327 | C4: 32 | D4: =48-6.5 -> 41.5 | E4: 17 | F4: 16 | G4: 357 | H4: 0 | I4: 0 | J4: =R4/6.2929-Q4+T4 -> 354.9397 | K4: 0 | L4: 0 | M4: 0 | N4: 0 | O4: =S4/6.2929-Q4+T4 -> 355.86518 | P4: 6.5 | Q4: 69 | R4: 2667.8101 | S4: 2673.6341 | T4: 0 | U4: 2667.8101 | V4: 2196.7771 | W4: =V4/6.2929 -> 349.0882 | X4: 349.17283 | Y4: 349.17283
A5: 2011 | B5: 361 | C5: 28 | D5: =48-6.5 -> 41.5 | E5: 56 | F5: 17 | G5: 388 | H5: 0 | I5: 0 | J5: =R5/6.2929-Q5+T5 -> 384.83272 | K5: 0 | L5: 0 | M5: 0 | N5: 0 | O5: =S5/6.2929-Q5+T5 -> 388.59903 | P5: 6.5 | Q5: 76 | R5: 2899.9742 | S5: 2923.6752 | T5: 0 | U5: 2899.9742 | V5: 2419.0307 | W5: =V5/6.2929 -> 384.40635 | X5: 384.4659 | Y5: 384.4659
A6: 2012 | B6: 361 | C6: 30 | D6: =48-6.5 -> 41.5 | E6: 74 | F6: 15 | G6: 441 | H6: 0 | I6: 0 | J6: =R6/6.2929-Q6+T6 -> 433.07878 | K6: 0 | L6: 0 | M6: 0 | N6: 0 | O6: =S6/6.2929-Q6+T6 -> 435.84037 | P6: 6.5 | Q6: 79 | R6: 3222.4606 | S6: 3239.839 | T6: 0 | U6: 3222.4606 | V6: 2710.8171 | W6: =V6/6.2929 -> 430.7739 | X6: 430.79504 | Y6: 430.79504
A7: 2013 | B7: 350 | C7: 32 | D7: =48-6.5 -> 41.5 | E7: 79 | F7: 15 | G7: 465 | H7: 11 | I7: 0 | J7: =R7/6.2929-Q7+T7 -> 474.34351 | K7: 0 | L7: 0 | M7: 0 | N7: 0 | O7: =S7/6.2929-Q7+T7 -> 477.79989 | P7: 6.5 | Q7: 79 | R7: 3450.6709 | S7: 3472.4215 | T7: 5 | U7: 3450.6709 | V7: 2942.6771 | W7: =V7/6.2929 -> 467.61861 | X7: 467.88835 | Y7: 467.88835
A8: 2014 | B8: 383 | C8: 31 | D8: =48-6.5 -> 41.5 | E8: 82 | F8: 16 | G8: 514 | H8: 25 | I8: 0 | J8: =R8/6.2929-Q8+T8 -> 530.82524 | K8: 0 | L8: 0 | M8: 0 | N8: 0 | O8: =S8/6.2929-Q8+T8 -> 508.8681 | P8: 6.5 | Q8: 83 | R8: 3799.8119 | S8: 3661.6378 | T8: 10 | U8: 3799.8119 | V8: 3188.1333 | W8: =V8/6.2929 -> 506.62387 | X8: 506.6833 | Y8: 506.6833
A9: 2015 | B9: 441 | C9: =280/6.2929 -> 44.494589 | D9: =48-6.5 -> 41.5 | E9: 95 | F9: 16 | G9: 544 | H9: 23 | I9: 0 | J9: =R9/6.2929-Q9+T9 -> 564.73461 | K9: 0 | L9: 0 | M9: 0 | N9: 0 | O9: =S9/6.2929-Q9+T9 -> 557.30065 | P9: 6.5 | Q9: 83 | R9: 3981.7356 | S9: 3934.9545 | T9: 15 | U9: 3981.7356 | V9: 3394.3287 | W9: =V9/6.2929 -> 539.39022 | X9: 541.27707 | Y9: 541.27707
A10: 2016 | B10: 450 | C10: =280/6.2929 -> 44.494589 | D10: =48-6.5 -> 41.5 | E10: 95 | F10: 16 | G10: 597 | H10: 52 | I10: 0 | J10: =R10/6.2929-Q10+T10 -> 565.07226 | K10: 0 | L10: 0 | M10: 0 | N10: 0 | O10: =S10/6.2929-Q10+T10 -> 619.72999 | P10: 6.5 | Q10: 79.3 | R10: 3910.2335 | S10: 4254.1891 | T10: 23 | U10: 3910.2335 | V10: 3472.4554 | W10: =V10/6.2929 -> 551.80527 | X10: 553.55108 | Y10: 553.55108
A11: 2017 | B11: 457 | C11: =280/6.2929 -> 44.494589 | D11: =48-6.5 -> 41.5 | E11: 95 | F11: 16 | G11: 628 | H11: 83 | I11: 0 | J11: =R11/6.2929-Q11+T11 -> 611.53038 | K11: 0 | L11: 0 | M11: 0 | N11: 0 | O11: =S11/6.2929-Q11+T11 -> 652.48306 | P11: 6.5 | Q11: 78 | R11: 4194.4091 | S11: 4452.1202 | T11: 23 | U11: 4194.4091 | V11: 3776.0591 | W11: =V11/6.2929 -> 600.05071 | X11: 602.20114 | Y11: 602.20114
A12: 2018 | B12: 457 | C12: =280/6.2929 -> 44.494589 | D12: =48-6.5 -> 41.5 | E12: 95 | F12: 16 | G12: 630 | H12: 69 | I12: 0 | J12: =R12/6.2929-Q12+T12 -> 666.47549 | K12: 0 | L12: 0 | M12: 0 | N12: 0 | O12: =S12/6.2929-Q12+T12 -> 685.48454 | P12: 6.5 | Q12: 78 | R12: 4540.1731 | S12: 4659.7951 | T12: 23 | U12: 4657.382 | V12: 4146.9923 | W12: =V12/6.2929 -> 658.99543 | X12: 663.13768 | Y12: 663.13768
A13: 2019 | B13: 457 | C13: =280/6.2929 -> 44.494589 | D13: =48-6.5 -> 41.5 | E13: 95 | F13: 16 | G13: 644 | H13: 17 | I13: 58 | J13: =R13/6.2929-Q13+T13 -> 696.08067 | K13: 0 | L13: 0 | M13: 0 | N13: 0 | O13: =S13/6.2929-Q13+T13 -> 715.76882 | P13: 6.5 | Q13: =Q12+50/6.2929 -> 85.945462 | R13: 4776.4755 | S13: 4900.3711 | T13: 23 | U13: 4801.8176 | V13: 4207.3856 | W13: =V13/6.2929 -> 668.59247 | X13: 665.00419 | Y13: 664.97623
A14: 2020 | B14: 457 | C14: =320/6.2929 -> 50.850959 | D14: =48-6.5 -> 41.5 | E14: 95 | F14: 35 | G14: 645 | H14: 18 | I14: 58 | J14: =R14/6.2929-Q14+T14 -> 713.57616 | K14: 0 | L14: 0 | M14: 0 | N14: 0 | O14: =S14/6.2929-Q14+T14 -> 754.76525 | P14: 6.5 | Q14: =95 -> 95 | R14: 4943.5522 | S14: 5202.751 | T14: 23 | U14: 5003.5315 | V14: 4399.7022 | W14: =V14/6.2929 -> 699.15336 | X14: 578.78969 | Y14: 580.14844
A15: 2021 | B15: 474 | C15: =320/6.2929 -> 50.850959 | D15: =48-6.5 -> 41.5 | E15: 104 | F15: 35 | G15: 646 | H15: 15 | I15: 58 | J15: =R15/6.2929-Q15+T15 -> 725.23101 | K15: 66 | L15: 55 | M15: 0 | N15: 0 | O15: =S15/6.2929-Q15+T15 -> 799.68896 | P15: 6.5 | Q15: =Q14 -> 95 | R15: 5016.895 | S15: 5485.4515 | T15: 23 | U15: 5093.3401 | V15: 4599.5395 | W15: =V15/6.2929 -> 730.90936 | X15: 658.34191 | Y15: 642.46025
A16: 2022 | B16: 474 | C16: =320/6.2929 -> 50.850959 | D16: =48-6.5 -> 41.5 | E16: 104 | F16: 35 | G16: 649 | H16: 17 | I16: 58 | J16: =R16/6.2929-Q16+T16 -> 737.50618 | K16: 131.89467 | L16: 96 | M16: =83/2 -> 41.5 | N16: 0 | O16: =S16/6.2929-Q16+T16 -> 834.89043 | P16: 6.5 | Q16: =Q15 -> 95 | R16: 5094.1414 | S16: 5706.9708 | T16: 23 | U16: 5226.2319 | V16: 4673.9683 | W16: =V16/6.2929 -> 742.73678 | X16: 700.41372 | Y16: 685.55336
A17: 2023 | B17: 474 | C17: =320/6.2929 -> 50.850959 | D17: =48-6.5 -> 41.5 | E17: 104 | F17: 35 | G17: 654 | H17: 23 | I17: 58 | J17: =R17/6.2929-Q17+T17 -> 748.65054 | K17: 131.89467 | L17: 96 | M17: 83.427355 | N17: 0 | O17: =S17/6.2929-Q17+T17 -> 868.29611 | P17: 6.5 | Q17: =Q16 -> 95 | R17: 5164.2718 | S17: 5917.1894 | T17: 23 | U17: 5297.1994 | V17: 4762.5459 | W17: =V17/6.2929 -> 756.81258 | X17: 717.12147 | Y17: 693.92846
A18: 2024 | B18: 474 | C18: =320/6.2929 -> 50.850959 | D18: =48-6.5 -> 41.5 | E18: 104 | F18: 35 | G18: 665 | H18: 33 | I18: 58 | J18: =R18/6.2929-Q18+T18 -> 754.2856 | K18: 131.89467 | L18: 96 | M18: 83.427355 | N18: =175/2 -> 87.5 | O18: =S18/6.2929-Q18+T18 -> 911.19436 | P18: 6.5 | Q18: =Q17 -> 95 | R18: 5199.7327 | S18: 6187.1438 | T18: 23 | U18: 5383.5318 | V18: 4923.9182 | W18: =V18/6.2929 -> 782.45613 | X18: 735.98657 | Y18: 702.50471
A19: 2025 | B19: 474 | C19: =320/6.2929 -> 50.850959 | D19: =48-6.5 -> 41.5 | E19: 104 | F19: 35 | G19: 674 | H19: 43 | I19: 58 | J19: =R19/6.2929-Q19+T19 -> 762.53002 | K19: 131.89467 | L19: 96 | M19: 83.427355 | N19: 174.80017 | O19: =S19/6.2929-Q19+T19 -> 946.24914 | P19: 6.5 | Q19: =Q18 -> 95 | R19: 5251.6139 | S19: 6407.74 | T19: 23 | U19: 5471.6786 | V19: 5116.7624 | W19: =V19/6.2929 -> 813.10086 | X19: 759.13165 | Y19: 713.88309
A20: 2026 | B20: 474 | C20: =320/6.2929 -> 50.850959 | D20: =48-6.5 -> 41.5 | E20: 104 | F20: 35 | G20: 695 | H20: 64 | I20: 58 | J20: =R20/6.2929-Q20+T20 -> 773.75231 | K20: 131.89467 | L20: 96 | M20: 83.427355 | N20: 174.80017 | O20: =S20/6.2929-Q20+T20 -> 986.61179 | P20: 6.5 | Q20: =Q19 -> 95 | R20: 5322.2347 | S20: 6661.7381 | T20: 23 | U20: 5581.2002 | V20: 5273.0193 | W20: =V20/6.2929 -> 837.93153 | X20: 780.09805 | Y20: 719.96336
A21: 2027 | B21: 474 | C21: =320/6.2929 -> 50.850959 | D21: =48-6.5 -> 41.5 | E21: 104 | F21: 35 | G21: 712 | H21: 80 | I21: 58 | J21: =R21/6.2929-Q21+T21 -> 782.1798 | K21: 131.89467 | L21: 96 | M21: 83.427355 | N21: 174.80017 | O21: =S21/6.2929-Q21+T21 -> 1017.1728 | P21: 6.5 | Q21: =Q20 -> 95 | R21: 5375.2681 | S21: 6854.0552 | T21: 23 | U21: 5665.8024 | V21: 5383.1211 | W21: =V21/6.2929 -> 855.42772 | X21: 806.75426 | Y21: 731.45865
A22: 2028 | B22: 474 | C22: =320/6.2929 -> 50.850959 | D22: =48-6.5 -> 41.5 | E22: 104 | F22: 35 | G22: 725 | H22: 94 | I22: 58 | J22: =R22/6.2929-Q22+T22 -> 791.51151 | K22: 131.89467 | L22: 96 | M22: 83.427355 | N22: 174.80017 | O22: =S22/6.2929-Q22+T22 -> 1049.644 | P22: 6.5 | Q22: =Q21 -> 95 | R22: 5433.9916 | S22: 7058.3937 | T22: 23 | U22: 5752.9744 | V22: 5414.0937 | W22: =V22/6.2929 -> 860.34955 | X22: 825.15607 | Y22: 740.62329
A23: 2029 | B23: 474 | C23: =320/6.2929 -> 50.850959 | D23: =48-6.5 -> 41.5 | E23: 104 | F23: 35 | G23: 737 | H23: 106 | I23: 58 | J23: =R23/6.2929-Q23+T23 -> 812.30426 | K23: 131.89467 | L23: 96 | M23: 83.427355 | N23: 174.80017 | O23: =S23/6.2929-Q23+T23 -> 1077.5188 | P23: 6.5 | Q23: =Q22 -> 95 | R23: 5564.8383 | S23: 7233.807 | T23: 23 | U23: 5782.697 | V23: 5497.8603 | W23: =V23/6.2929 -> 873.66084 | X23: 840.97653 | Y23: 748.37602
A24: 2030 | B24: 474 | C24: =320/6.2929 -> 50.850959 | D24: =48-6.5 -> 41.5 | E24: 104 | F24: 35 | G24: 750 | H24: 119 | I24: 58 | J24: =R24/6.2929-Q24+T24 -> 831.93654 | K24: 131.89467 | L24: 96 | M24: 83.427355 | N24: 174.80017 | O24: =S24/6.2929-Q24+T24 -> 1112.7314 | P24: 6.5 | Q24: =Q23 -> 95 | R24: 5688.3823 | S24: 7455.3963 | T24: 23 | U24: 5866.7319 | V24: 5614.8826 | W24: =V24/6.2929 -> 892.25676 | X24: 853.91554 | Y24: 754.07162
A25: 2031 | B25: 474 | C25: =320/6.2929 -> 50.850959 | D25: =48-6.5 -> 41.5 | E25: 104 | F25: 35 | G25: 762 | H25: 130 | I25: 58 | J25: =R25/6.2929-Q25+T25 -> 850.906 | K25: 131.89467 | L25: 96 | M25: 83.427355 | N25: 174.80017 | P25: 6.5 | Q25: =Q24 -> 95 | R25: 5807.7552 | T25: 23 | U25: 5949.4698 | V25: 5741.2155 | W25: =V25/6.2929 -> 912.33223 | X25: 868.03837 | Y25: 760.15432
A26: 2032 | B26: 474 | C26: =320/6.2929 -> 50.850959 | D26: =48-6.5 -> 41.5 | E26: 104 | F26: 35 | G26: 770 | H26: 139 | I26: 58 | J26: =R26/6.2929-Q26+T26 -> 864.33005 | K26: 131.89467 | L26: 96 | M26: 83.427355 | N26: 174.80017 | P26: 6.5 | Q26: =Q25 -> 95 | R26: 5892.2313 | T26: 23 | U26: 6023.0604 | V26: 5802.2369 | W26: =V26/6.2929 -> 922.02909 | X26: 874.21243 | Y26: 760.92373
A27: 2033 | B27: 474 | C27: =320/6.2929 -> 50.850959 | D27: =48-6.5 -> 41.5 | E27: 104 | F27: 35 | G27: 778 | H27: 147 | I27: 58 | J27: =R27/6.2929-Q27+T27 -> 881.59724 | K27: 131.89467 | L27: 96 | M27: 83.427355 | N27: 174.80017 | P27: 6.5 | Q27: =Q26 -> 95 | R27: 6000.892 | T27: 23 | U27: 6139.2517 | V27: 5934.2647 | W27: =V27/6.2929 -> 943.00954 | X27: 895.96606 | Y27: 773.35432
A28: 2034 | B28: 474 | C28: =320/6.2929 -> 50.850959 | D28: =48-6.5 -> 41.5 | E28: 104 | F28: 35 | G28: 787 | H28: 155 | I28: 58 | J28: =R28/6.2929-Q28+T28 -> 896.22214 | K28: 131.89467 | L28: 96 | M28: 83.427355 | N28: 174.80017 | P28: 6.5 | Q28: =Q27 -> 95 | R28: 6092.9251 | T28: 23 | U28: 6254.0171 | V28: 5994.6236 | W28: =V28/6.2929 -> 952.60113 | X28: 911.82228 | Y28: 782.81205
A29: 2035 | B29: 474 | C29: =320/6.2929 -> 50.850959 | D29: =48-6.5 -> 41.5 | E29: 104 | F29: 35 | G29: 794 | H29: 163 | I29: 58 | J29: =R29/6.2929-Q29+T29 -> 906.35844 | K29: 131.89467 | L29: 96 | M29: 83.427355 | N29: 174.80017 | P29: 6.5 | Q29: =Q28 -> 95 | R29: 6156.7118 | T29: 23 | U29: 6335.601 | V29: 6001.8983 | W29: =V29/6.2929 -> 953.75714 | X29: 916.56947 | Y29: 783.35164
A30: 2036 | B30: 474 | C30: =320/6.2929 -> 50.850959 | D30: =48-6.5 -> 41.5 | E30: 104 | F30: 35 | G30: 799 | H30: 168 | I30: 58 | K30: 131.89467 | L30: 96 | M30: 83.427355 | N30: 174.80017 | P30: 6.5 | Q30: =Q29 -> 95 | T30: 23 | V30: 5996.0388 | W30: =V30/6.2929 -> 952.82601 | X30: 916.34071 | Y30: 774.98482
A31: 2037 | B31: 474 | C31: =320/6.2929 -> 50.850959 | D31: =48-6.5 -> 41.5 | E31: 104 | F31: 35 | G31: 804 | H31: 172 | I31: 58 | K31: 131.89467 | L31: 96 | M31: 83.427355 | N31: 174.80017 | P31: 6.5 | Q31: =Q30 -> 95 | T31: 23 | V31: 6056.2272 | W31: =V31/6.2929 -> 962.3905 | X31: 928.20503 | Y31: 773.50345
A32: 2038 | B32: 474 | C32: =320/6.2929 -> 50.850959 | D32: =48-6.5 -> 41.5 | E32: 104 | F32: 35 | G32: 810 | H32: 178 | I32: 58 | K32: 131.89467 | L32: 96 | M32: 83.427355 | N32: 174.80017 | P32: 6.5 | Q32: =Q31 -> 95 | T32: 23 | V32: 6083.2094 | W32: =V32/6.2929 -> 966.67823 | X32: 932.79349 | Y32: 767.7116
A33: 2039 | B33: 474 | C33: =320/6.2929 -> 50.850959 | D33: =48-6.5 -> 41.5 | E33: 104 | F33: 35 | G33: 815 | H33: 184 | I33: 58 | K33: 131.89467 | L33: 96 | M33: 83.427355 | N33: 174.80017 | P33: 6.5 | Q33: =Q32 -> 95 | T33: 23 | V33: 6140.8698 | W33: =V33/6.2929 -> 975.841 | X33: 941.85963 | Y33: 768.65402
A34: 2040 | B34: 474 | C34: =320/6.2929 -> 50.850959 | D34: =48-6.5 -> 41.5 | E34: 104 | F34: 35 | G34: 818 | H34: 187 | I34: 58 | K34: 131.89467 | L34: 96 | M34: 83.427355 | N34: 174.80017 | P34: 6.5 | Q34: =Q33 -> 95 | T34: 23 | V34: 6171.5513 | W34: =V34/6.2929 -> 980.71657 | X34: 940.72079 | Y34: 762.84175
A35: 2041 | B35: 474 | C35: =320/6.2929 -> 50.850959 | D35: =48-6.5 -> 41.5 | E35: 104 | F35: 35 | G35: 818 | H35: 187 | I35: 58 | K35: 131.89467 | L35: 96 | M35: 83.427355 | N35: 174.80017 | P35: 6.5 | Q35: =Q34 -> 95 | T35: 23 | X35: 944.30106 | Y35: 760.54081
A36: 2042 | B36: 474 | C36: =320/6.2929 -> 50.850959 | D36: =48-6.5 -> 41.5 | E36: 104 | F36: 35 | G36: 818 | H36: 187 | I36: 58 | K36: 131.89467 | L36: 96 | M36: 83.427355 | N36: 174.80017 | P36: 6.5 | Q36: =Q35 -> 95 | T36: 23 | X36: 948.17994 | Y36: 756.3087
A37: 2043 | B37: 474 | C37: =320/6.2929 -> 50.850959 | D37: =48-6.5 -> 41.5 | E37: 104 | F37: 35 | G37: 818 | H37: 187 | I37: 58 | K37: 131.89467 | L37: 96 | M37: 83.427355 | N37: 174.80017 | P37: 6.5 | Q37: =Q36 -> 95 | T37: 23 | X37: 953.39959 | Y37: 754.02165
A38: 2044 | B38: 474 | C38: =320/6.2929 -> 50.850959 | D38: =48-6.5 -> 41.5 | E38: 104 | F38: 35 | G38: 818 | H38: 187 | I38: 58 | K38: 131.89467 | L38: 96 | M38: 83.427355 | N38: 174.80017 | P38: 6.5 | Q38: =Q37 -> 95 | T38: 23 | X38: 957.16081 | Y38: 751.58523
A39: 2045 | B39: 474 | C39: =320/6.2929 -> 50.850959 | D39: =48-6.5 -> 41.5 | E39: 104 | F39: 35 | G39: 818 | H39: 187 | I39: 58 | K39: 131.89467 | L39: 96 | M39: 83.427355 | N39: 174.80017 | P39: 6.5 | Q39: =Q38 -> 95 | T39: 23 | X39: 963.44485 | Y39: 749.42954
A40: 2046 | B40: 474 | C40: =320/6.2929 -> 50.850959 | D40: =48-6.5 -> 41.5 | E40: 104 | F40: 35 | G40: 818 | H40: 187 | I40: 58 | K40: 131.89467 | L40: 96 | M40: 83.427355 | N40: 174.80017 | P40: 6.5 | Q40: =Q39 -> 95 | T40: 23 | X40: 967.98263 | Y40: 744.97725
...

Sheet bbld
A1: Date | B1: ='10.7'!B3 -> Enbridge Mainline | C1: ='10.7'!C3 -> Express | D1: ='10.7'!D3 -> Trans Mountain | E1: ='10.7'!E3 -> Keystone | F1: ='10.7'!F3 -> Rangeland/Milk River | G1: ='10.7'!G3 -> NEB 2016 Offtake | H1: ='10.7'!H3 -> Implied Rail | I1: ='10.7'!I3 -> Enbridge Expansions | ... T1: ='10.7'!T3 -> Enbridge Bakken Volumes
A2: ='10.7'!A4 -> 2010 | B2: ='10.7'!B4*6.2929 -> 2057.7783 | C2: ='10.7'!C4*6.2929 -> 201.3728 | D2: ='10.7'!D4*6.2929 -> 261.15535 | E2: ='10.7'!E4*6.2929 -> 106.9793 | F2: ='10.7'!F4*6.2929 -> 100.6864 | G2: ='10.7'!G4*6.2929 -> 2246.5653 | H2: ='10.7'!H4*6.2929 -> 0 | I2: ='10.7'!I4*6.2929 -> 0 | ... T2: ='10.7'!T4*6.2929 -> 0
A3: ='10.7'!A5 -> 2011 | B3: ='10.7'!B5*6.2929 -> 2271.7369 | C3: ='10.7'!C5*6.2929 -> 176.2012 | D3: ='10.7'!D5*6.2929 -> 261.15535 | E3: ='10.7'!E5*6.2929 -> 352.4024 | F3: ='10.7'!F5*6.2929 -> 106.9793 | G3: ='10.7'!G5*6.2929 -> 2441.6452 | H3: ='10.7'!H5*6.2929 -> 0 | I3: ='10.7'!I5*6.2929 -> 0 | ... T3: ='10.7'!T5*6.2929 -> 0
A4: ='10.7'!A6 -> 2012 | B4: ='10.7'!B6*6.2929 -> 2271.7369 | C4: ='10.7'!C6*6.2929 -> 188.787 | D4: ='10.7'!D6*6.2929 -> 261.15535 | E4: ='10.7'!E6*6.2929 -> 465.6746 | F4: ='10.7'!F6*6.2929 -> 94.3935 | G4: ='10.7'!G6*6.2929 -> 2775.1689 | H4: ='10.7'!H6*6.2929 -> 0 | I4: ='10.7'!I6*6.2929 -> 0 | ... T4: ='10.7'!T6*6.2929 -> 0
A5: ='10.7'!A7 -> 2013 | B5: ='10.7'!B7*6.2929 -> 2202.515 | C5: ='10.7'!C7*6.2929 -> 201.3728 | D5: ='10.7'!D7*6.2929 -> 261.15535 | E5: ='10.7'!E7*6.2929 -> 497.1391 | F5: ='10.7'!F7*6.2929 -> 94.3935 | G5: ='10.7'!G7*6.2929 -> 2926.1985 | H5: ='10.7'!H7*6.2929 -> 69.2219 | I5: ='10.7'!I7*6.2929 -> 0 | ... T5: ='10.7'!T7*6.2929 -> 31.4645
A6: ='10.7'!A8 -> 2014 | B6: ='10.7'!B8*6.2929 -> 2410.1807 | C6: ='10.7'!C8*6.2929 -> 195.0799 | D6: ='10.7'!D8*6.2929 -> 261.15535 | E6: ='10.7'!E8*6.2929 -> 516.0178 | F6: ='10.7'!F8*6.2929 -> 100.6864 | G6: ='10.7'!G8*6.2929 -> 3234.5506 | H6: ='10.7'!H8*6.2929 -> 157.3225 | I6: ='10.7'!I8*6.2929 -> 0 | ... T6: ='10.7'!T8*6.2929 -> 62.929
A7: ='10.7'!A9 -> 2015 | B7: ='10.7'!B9*6.2929 -> 2775.1689 | C7: ='10.7'!C9*6.2929 -> 280 | D7: ='10.7'!D9*6.2929 -> 261.15535 | E7: ='10.7'!E9*6.2929 -> 597.8255 | F7: ='10.7'!F9*6.2929 -> 100.6864 | G7: ='10.7'!G9*6.2929 -> 3423.3376 | H7: ='10.7'!H9*6.2929 -> 144.7367 | I7: ='10.7'!I9*6.2929 -> 0 | ... T7: ='10.7'!T9*6.2929 -> 94.3935
A8: ='10.7'!A10 -> 2016 | B8: ='10.7'!B10*6.2929 -> 2831.805 | C8: ='10.7'!C10*6.2929 -> 280 | D8: ='10.7'!D10*6.2929 -> 261.15535 | E8: ='10.7'!E10*6.2929 -> 597.8255 | F8: ='10.7'!F10*6.2929 -> 100.6864 | G8: ='10.7'!G10*6.2929 -> 3756.8613 | H8: ='10.7'!H10*6.2929 -> 327.2308 | I8: ='10.7'!I10*6.2929 -> 0 | ... T8: ='10.7'!T10*6.2929 -> 144.7367
A9: ='10.7'!A11 -> 2017 | B9: ='10.7'!B11*6.2929 -> 2875.8553 | C9: ='10.7'!C11*6.2929 -> 280 | D9: ='10.7'!D11*6.2929 -> 261.15535 | E9: ='10.7'!E11*6.2929 -> 597.8255 | F9: ='10.7'!F11*6.2929 -> 100.6864 | G9: ='10.7'!G11*6.2929 -> 3951.9412 | H9: ='10.7'!H11*6.2929 -> 522.3107 | I9: ='10.7'!I11*6.2929 -> 0 | ... T9: ='10.7'!T11*6.2929 -> 144.7367
A10: ='10.7'!A12 -> 2018 | B10: ='10.7'!B12*6.2929 -> 2875.8553 | C10: ='10.7'!C12*6.2929 -> 280 | D10: ='10.7'!D12*6.2929 -> 261.15535 | E10: ='10.7'!E12*6.2929 -> 597.8255 | F10: ='10.7'!F12*6.2929 -> 100.6864 | G10: ='10.7'!G12*6.2929 -> 3964.527 | H10: ='10.7'!H12*6.2929 -> 434.2101 | I10: ='10.7'!I12*6.2929 -> 0 | ... T10: ='10.7'!T12*6.2929 -> 144.7367
A11: ='10.7'!A13 -> 2019 | B11: ='10.7'!B13*6.2929 -> 2875.8553 | C11: ='10.7'!C13*6.2929 -> 280 | D11: ='10.7'!D13*6.2929 -> 261.15535 | E11: ='10.7'!E13*6.2929 -> 597.8255 | F11: ='10.7'!F13*6.2929 -> 100.6864 | G11: ='10.7'!G13*6.2929 -> 4052.6276 | H11: ='10.7'!H13*6.2929 -> 106.9793 | I11: ='10.7'!I13*6.2929 -> 364.9882 | ... T11: ='10.7'!T13*6.2929 -> 144.7367
A12: ='10.7'!A14 -> 2020 | B12: ='10.7'!B14*6.2929 -> 2875.8553 | C12: ='10.7'!C14*6.2929 -> 320 | D12: ='10.7'!D14*6.2929 -> 261.15535 | E12: ='10.7'!E14*6.2929 -> 597.8255 | F12: ='10.7'!F14*6.2929 -> 220.2515 | G12: ='10.7'!G14*6.2929 -> 4058.9205 | H12: ='10.7'!H14*6.2929 -> 113.2722 | I12: ='10.7'!I14*6.2929 -> 364.9882 | ... T12: ='10.7'!T14*6.2929 -> 144.7367
A13: ='10.7'!A15 -> 2021 | B13: ='10.7'!B15*6.2929 -> 2982.8346 | C13: ='10.7'!C15*6.2929 -> 320 | D13: ='10.7'!D15*6.2929 -> 261.15535 | E13: ='10.7'!E15*6.2929 -> 654.4616 | F13: ='10.7'!F15*6.2929 -> 220.2515 | G13: ='10.7'!G15*6.2929 -> 4065.2134 | H13: ='10.7'!H15*6.2929 -> 94.3935 | I13: ='10.7'!I15*6.2929 -> 364.9882 | ... T13: ='10.7'!T15*6.2929 -> 144.7367
... A22: ='10.7'!A24 -> 2030 | B22: ='10.7'!B24*6.2929 -> 2982.8346 | C22: ='10.7'!C24*6.2929 -> 320 | D22: ='10.7'!D24*6.2929 -> 261.15535 | E22: ='10.7'!E24*6.2929 -> 654.4616 | F22: ='10.7'!F24*6.2929 -> 220.2515 | G22: ='10.7'!G24*6.2929 -> 4719.675 | H22: ='10.7'!H24*6.2929 -> 748.8551 | I22: ='10.7'!I24*6.2929 -> 364.9882 | ... T22: ='10.7'!T24*6.2929 -> 144.7367
B24: Enb | C24: Rockies | D24: Keystone | E24: TMX | F24: TM | G24: KM-Canada | H24: KXL | I24: Refineries | J24: Supply (net refinery demand ex burnaby production, incl ref prod to BC) | M24: Supply, no growth
A25: Me: | B25: 3241 | C25: 380 | D25: 598 | E25: =L22 -> 604.1184 | F25: 261 | G25: =E25+F25 -> 865.1184 | H25: 830 | I25: 541 | J25: =J22 -> 5235.2935 | M25: =J10 -> 4194.0636
A26: Greg | B26: 3679 | C26: 403 | D26: 561 | E26: 561 | F26: 314 | G26: =E26+F26 -> 875 | H26: 789 | I26: 662 | J26: =6012-I26+50+41 -> 5441 | M26: =4446-I26+50+41 -> 3875

Sheet 2020ES.8
A1: Figure ES.8: Crude oil pipeline capacity vs. total supply available for export, Evolving and Reference Scenarios
A2: MMb/d
B3: Total Supply Available for Export EVO | C3: Express | D3: Milk River | E3: Aurora/Rangeland | F3: TransMountain | G3: Enbridge Mainline | H3: Keystone | I3: Enbridge Line 3 (2021) | J3: TMX (2023) | K3: Keystone XL (2023) | L3: Rail | M3: Total net rail and KXL | N3: Total Supply Available for Export REF | O3: Ref shortfall | P3: evolvinc shortfall | Q3: Express | R3: Milk River | S3: Aurora/Rangeland | T3: Rangeland/Milk River | U3: TransMountain | V3: Enbridge Mainline | W3: Keystone | X3: Enbridge Line 3 (2021) | Y3: TMX (2023) | Z3: Keystone XL (2023) | AA3: Rail
A4: 2010 | B4: 2.1973097 | C4: 0.27719062 | D4: 0.096917721 | E4: 0.0441 | F4: 0.2987655 | G4: 2.0964428 | H4: 0.1015075 | I4: 0 | J4: 0 | K4: 0 | L4: 0 | M4: =SUM(C4:L4)-K4 -> 2.9149241 | N4: 2.1973097 | O4: =N4-M4 -> -0.7176144 | P4: =B4-M4 -> -0.7176144 | Q4: =C4/6.2998*1000 -> 43.999908 | R4: =D4/6.2998*1000 -> 15.384254 | S4: =E4/6.2998*1000 -> 7.0002222 | T4: =R4+S4 -> 22.384476 | U4: =F4/6.2998*1000 -> 47.424601 | V4: =G4/6.2998*1000 -> 332.77926 | W4: =H4/6.2998*1000 -> 16.112813 | X4: =I4/6.2998*1000 -> 0 | Y4: =J4/6.2998*1000 -> 0 | Z4: =K4/6.2998*1000 -> 0 | AA4: =L4/6.2998*1000 -> 0
A5: 2011 | B5: 2.4194055 | C5: 0.27719062 | D5: 0.096917721 | E5: 0.0441 | F5: 0.2736063 | G5: 2.169981 | H5: 0.44583063 | I5: 0 | J5: 0 | K5: 0 | L5: 0 | M5: =SUM(C5:L5)-K5 -> 3.3076263 | N5: 2.4194055 | O5: =N5-M5 -> -0.8882208 | P5: =B5-M5 -> -0.8882208 | Q5: =C5/6.2998*1000 -> 43.999908 | R5: =D5/6.2998*1000 -> 15.384254 | S5: =E5/6.2998*1000 -> 7.0002222 | T5: =R5+S5 -> 22.384476 | U5: =F5/6.2998*1000 -> 43.43095 | V5: =G5/6.2998*1000 -> 344.45236 | W5: =H5/6.2998*1000 -> 70.769014 | X5: =I5/6.2998*1000 -> 0 | Y5: =J5/6.2998*1000 -> 0 | Z5: =K5/6.2998*1000 -> 0 | AA5: =L5/6.2998*1000 -> 0
A6: 2012 | B6: 2.7109501 | C6: 0.27719062 | D6: 0.096917721 | E6: 0.0441 | F6: 0.2809444 | G6: 2.1482288 | H6: 0.52815328 | I6: 0 | J6: 0 | K6: 0 | L6: 0.046191712 | M6: =SUM(C6:L6)-K6 -> 3.4217265 | N6: 2.7109501 | O6: =N6-M6 -> -0.71077641 | P6: =B6-M6 -> -0.71077641 | Q6: =C6/6.2998*1000 -> 43.999908 | R6: =D6/6.2998*1000 -> 15.384254 | S6: =E6/6.2998*1000 -> 7.0002222 | T6: =R6+S6 -> 22.384476 | U6: =F6/6.2998*1000 -> 44.595765 | V6: =G6/6.2998*1000 -> 340.99952 | W6: =H6/6.2998*1000 -> 83.836515 | X6: =I6/6.2998*1000 -> 0 | Y6: =J6/6.2998*1000 -> 0 | Z6: =K6/6.2998*1000 -> 0 | AA6: =L6/6.2998*1000 -> 7.3322505
A7: 2013 | B7: 2.9443746 | C7: 0.27719062 | D7: 0.096917721 | E7: 0.0441 | F7: 0.2704614 | G7: 2.2075211 | H7: 0.52777188 | I7: 0 | J7: 0 | K7: 0 | L7: 0.12607271 | M7: =SUM(C7:L7)-K7 -> 3.5500355 | N7: 2.9443746 | O7: =N7-M7 -> -0.60566085 | P7: =B7-M7 -> -0.60566085 | Q7: =C7/6.2998*1000 -> 43.999908 | R7: =D7/6.2998*1000 -> 15.384254 | S7: =E7/6.2998*1000 -> 7.0002222 | T7: =R7+S7 -> 22.384476 | U7: =F7/6.2998*1000 -> 42.931744 | V7: =G7/6.2998*1000 -> 350.41131 | W7: =H7/6.2998*1000 -> 83.775973 | X7: =I7/6.2998*1000 -> 0 | Y7: =J7/6.2998*1000 -> 0 | Z7: =K7/6.2998*1000 -> 0 | AA7: =L7/6.2998*1000 -> 20.012177
A8: 2014 | B8: 3.1885074 | C8: 0.27719062 | D8: 0.096917721 | E8: 0.0441 | F8: 0.283041 | G8: 2.3426166 | H8: 0.53467493 | I8: 0 | J8: 0 | K8: 0 | L8: 0.16096082 | M8: =SUM(C8:L8)-K8 -> 3.7395017 | N8: 3.1885074 | O8: =N8-M8 -> -0.55099436 | P8: =B8-M8 -> -0.55099436 | Q8: =C8/6.2998*1000 -> 43.999908 | R8: =D8/6.2998*1000 -> 15.384254 | S8: =E8/6.2998*1000 -> 7.0002222 | T8: =R8+S8 -> 22.384476 | U8: =F8/6.2998*1000 -> 44.928569 | V8: =G8/6.2998*1000 -> 371.85571 | W8: =H8/6.2998*1000 -> 84.871731 | X8: =I8/6.2998*1000 -> 0 | Y8: =J8/6.2998*1000 -> 0 | Z8: =K8/6.2998*1000 -> 0 | AA8: =L8/6.2998*1000 -> 25.550147
A9: 2015 | B9: 3.4062025 | C9: 0.27719062 | D9: 0.096917721 | E9: 0.0441 | F9: 0.30872435 | G9: 2.5198034 | H9: 0.57552718 | I9: 0 | J9: 0 | K9: 0 | L9: 0.11121978 | M9: =SUM(C9:L9)-K9 -> 3.9334831 | N9: 3.4062025 | O9: =N9-M9 -> -0.52728059 | P9: =B9-M9 -> -0.52728059 | Q9: =C9/6.2998*1000 -> 43.999908 | R9: =D9/6.2998*1000 -> 15.384254 | S9: =E9/6.2998*1000 -> 7.0002222 | T9: =R9+S9 -> 22.384476 | U9: =F9/6.2998*1000 -> 49.005421 | V9: =G9/6.2998*1000 -> 399.9815 | W9: =H9/6.2998*1000 -> 91.356421 | X9: =I9/6.2998*1000 -> 0 | Y9: =J9/6.2998*1000 -> 0 | Z9: =K9/6.2998*1000 -> 0 | AA9: =L9/6.2998*1000 -> 17.654493
A10: 2016 | B10: 3.4834416 | C10: 0.27719062 | D10: 0.096917721 | E10: 0.0441 | F10: 0.31291755 | G10: 2.7601341 | H10: 0.57109287 | I10: 0 | J10: 0 | K10: 0 | L10: 0.08789001 | M10: =SUM(C10:L10)-K10 -> 4.1502428 | N10: 3.4834416 | O10: =N10-M10 -> -0.66680123 | P10: =B10-M10 -> -0.66680123 | Q10: =C10/6.2998*1000 -> 43.999908 | R10: =D10/6.2998*1000 -> 15.384254 | S10: =E10/6.2998*1000 -> 7.0002222 | T10: =R10+S10 -> 22.384476 | U10: =F10/6.2998*1000 -> 49.671029 | V10: =G10/6.2998*1000 -> 438.13043 | W10: =H10/6.2998*1000 -> 90.65254 | X10: =I10/6.2998*1000 -> 0 | Y10: =J10/6.2998*1000 -> 0 | Z10: =K10/6.2998*1000 -> 0 | AA10: =L10/6.2998*1000 -> 13.951238
A11: 2017 | B11: 3.7895916 | C11: 0.27719062 | D11: 0.096917721 | E11: 0.0441 | F11: 0.30977265 | G11: 2.8148579 | H11: 0.5892966 | I11: 0 | J11: 0 | K11: 0 | L11: 0.13188297 | M11: =SUM(C11:L11)-K11 -> 4.2640185 | N11: 3.7895916 | O11: =N11-M11 -> -0.47442696 | P11: =B11-M11 -> -0.47442696 | Q11: =C11/6.2998*1000 -> 43.999908 | R11: =D11/6.2998*1000 -> 15.384254 | S11: =E11/6.2998*1000 -> 7.0002222 | T11: =R11+S11 -> 22.384476 | U11: =F11/6.2998*1000 -> 49.171823 | V11: =G11/6.2998*1000 -> 446.81703 | W11: =H11/6.2998*1000 -> 93.542113 | X11: =I11/6.2998*1000 -> 0 | Y11: =J11/6.2998*1000 -> 0 | Z11: =K11/6.2998*1000 -> 0 | AA11: =L11/6.2998*1000 -> 20.93447
A12: 2018 | B12: 4.1730591 | C12: 0.27719062 | D12: 0.096917721 | E12: 0.0441 | F12: 0.28880665 | G12: 2.7771401 | H12: 0.58923371 | I12: 0 | J12: 0 | K12: 0 | L12: 0.24156875 | M12: =SUM(C12:L12)-K12 -> 4.3149576 | N12: 4.1730591 | O12: =N12-M12 -> -0.14189847 | P12: =B12-M12 -> -0.14189847 | Q12: =C12/6.2998*1000 -> 43.999908 | R12: =D12/6.2998*1000 -> 15.384254 | S12: =E12/6.2998*1000 -> 7.0002222 | T12: =R12+S12 -> 22.384476 | U12: =F12/6.2998*1000 -> 45.843781 | V12: =G12/6.2998*1000 -> 440.82989 | W12: =H12/6.2998*1000 -> 93.532129 | X12: =I12/6.2998*1000 -> 0 | Y12: =J12/6.2998*1000 -> 0 | Z12: =K12/6.2998*1000 -> 0 | AA12: =L12/6.2998*1000 -> 38.345464
A13: 2019 | B13: 4.1846289 | C13: 0.27719062 | D13: 0.096917721 | E13: 0.0491 | F13: 0.3155383 | G13: 2.8197787 | H13: 0.58419138 | I13: 0 | J13: 0 | K13: 0 | L13: 0.28027212 | M13: =SUM(C13:L13)-K13 -> 4.4229888 | N13: 4.1848049 | O13: =N13-M13 -> -0.23818393 | P13: =B13-M13 -> -0.23835987 | Q13: =C13/6.2998*1000 -> 43.999908 | R13: =D13/6.2998*1000 -> 15.384254 | S13: =E13/6.2998*1000 -> 7.7938982 | T13: =R13+S13 -> 23.178152 | U13: =F13/6.2998*1000 -> 50.087035 | V13: =G13/6.2998*1000 -> 447.59812 | W13: =H13/6.2998*1000 -> 92.731735 | X13: =I13/6.2998*1000 -> 0 | Y13: =J13/6.2998*1000 -> 0 | Z13: =K13/6.2998*1000 -> 0 | AA13: =L13/6.2998*1000 -> 44.489051
A14: 2020 | B14: 3.6508161 | C14: 0.31094062 | D14: 0.096917721 | E14: 0.1066 | F14: 0.3019104 | G14: 2.9605186 | H14: 0.57711012 | I14: 0.04 | J14: 0 | K14: 0 | L14: 0.15351777 | M14: =SUM(C14:L14)-K14 -> 4.5475152 | N14: 3.6422657 | O14: =N14-M14 -> -0.90524956 | P14: =B14-M14 -> -0.89669909 | Q14: =C14/6.2998*1000 -> 49.357221 | R14: =D14/6.2998*1000 -> 15.384254 | S14: =E14/6.2998*1000 -> 16.921172 | T14: =R14+S14 -> 32.305426 | U14: =F14/6.2998*1000 -> 47.923807 | V14: =G14/6.2998*1000 -> 469.9385 | W14: =H14/6.2998*1000 -> 91.607688 | X14: =I14/6.2998*1000 -> 6.3494079 | Y14: =J14/6.2998*1000 -> 0 | Z14: =K14/6.2998*1000 -> 0 | AA14: =L14/6.2998*1000 -> 24.368674
A15: 2021 | B15: 4.0429381 | C15: 0.32219062 | D15: 0.096917721 | E15: 0.1241 | F15: 0.30945816 | G15: 2.9798789 | H15: 0.57711012 | I15: 0.18 | J15: 0 | K15: 0 | L15: 0.1512861 | M15: =SUM(C15:L15)-K15 -> 4.7409416 | N15: 4.1428798 | O15: =N15-M15 -> -0.59806177 | P15: =B15-M15 -> -0.69800343 | Q15: =C15/6.2998*1000 -> 51.142992 | R15: =D15/6.2998*1000 -> 15.384254 | S15: =E15/6.2998*1000 -> 19.699038 | T15: =R15+S15 -> 35.083292 | U15: =F15/6.2998*1000 -> 49.121902 | V15: =G15/6.2998*1000 -> 473.01166 | W15: =H15/6.2998*1000 -> 91.607688 | X15: =I15/6.2998*1000 -> 28.572336 | Y15: =J15/6.2998*1000 -> 0 | Z15: =K15/6.2998*1000 -> 0 | AA15: =L15/6.2998*1000 -> 24.014429
... A44: 2050 | B44: 4.5743246 | C44: 0.32219062 | D44: 0.096917721 | E44: 0.1241 | F44: 0.30945816 | G44: 2.9798789 | H44: 0.65211012 | I44: 0.33 | J44: 0.54 | K44: 0.83 | L44: 0.175 | M44: =SUM(C44:L44)-K44 -> 5.5296555 | N44: 6.1208569 | O44: =N44-M44 -> 0.59120139 | P44: =B44-M44 -> -0.95533084 | Q44: =C44/6.2998*1000 -> 51.142992 | R44: =D44/6.2998*1000 -> 15.384254 | S44: =E44/6.2998*1000 -> 19.699038 | T44: =R44+S44 -> 35.083292 | U44: =F44/6.2998*1000 -> 49.121902 | V44: =G44/6.2998*1000 -> 473.01166 | W44: =H44/6.2998*1000 -> 103.51283 | X44: =I44/6.2998*1000 -> 52.382615 | Y44: =J44/6.2998*1000 -> 85.717007 | Z44: =K44/6.2998*1000 -> 131.75021 | AA44: =L44/6.2998*1000 -> 27.77866
B45: =B29/B14 -> 1.3502607 | N45: =N44/N14 -> 1.6805081

Sheet R.33
A1: Figure R.33: Illustrative export capacity from pipelines and structural rail, crude oil pipeline capacity vs. total supply available for export, all scenarios
A2: =HYPERLINK("#'Table of Contents'!A1","Return to Table of Contents") -> Return to Table of Contents
A6: Year | B6: Total Pipeline Capacity and Structural Rail | C6: Total Supply Available for Export - Current Measures | D6: Total Supply Available for Export - Global Net-zero | E6: Total Supply Available for Export - Canada Net-zero | F6: Unit
A7: 2010 | B7: 2.9149241 | C7: 2.2963628 | D7: 2.2963628 | E7: 2.2963628 | F7: Million barrels per day (MMb/d) | O7: Name | P7: bbb/d | Q7: m3 | R7: Capacity assumptions
A8: 2011 | B8: 3.3076263 | C8: 2.4855282 | D8: 2.4855282 | E8: 2.4855282 | F8: Million barrels per day (MMb/d) | O8: Enbridge Mainline | P8: 3290 | Q8: =P8*0.158987 -> 523.06723 | R8: Stated capacity includes the fully completed Line 3 Replacement Project which added 370 Mb/d of capacity to the Enbridge Mainline in late 2021.
A9: 2012 | B9: 3.3888681 | C9: 2.8361069 | D9: 2.8361069 | E9: 2.8361069 | F9: Million barrels per day (MMb/d) | O9: Keystone | P9: 590 | Q9: =P9*0.158987 -> 93.80233 | R9: Capacity held fixed over the projection period. The cancelled Keystone XL project is not included in Figure R.33.
A10: 2013 | B10: 3.4589628 | C10: 3.0849245 | D10: 3.0849245 | E10: 3.0849245 | F10: Million barrels per day (MMb/d) | O10: Trans Mountain | P10: 300 | Q10: =P10*0.158987 -> 47.6961 | R10: Capacity is held fixed over the projection period.
A11: 2014 | B11: 3.6135409 | C11: 3.4544679 | D11: 3.4544679 | E11: 3.4544679 | F11: Million barrels per day (MMb/d) | O11: Trans Mountain Expansion | P11: 590 | Q11: =P11*0.158987 -> 93.80233 | R11: The Trans Mountain Expansion Project adds capacity starting in the first quarter of 2024 and increases to full capacity a few months later. This includes use of drag-reducing agents, which increase the capacity of the existing Trans Mountain line by 50 Mb/d.
A12: 2015 | B12: 3.8622633 | C12: 3.5762824 | D12: 3.5762824 | E12: 3.5762824 | F12: Million barrels per day (MMb/d) | O12: Express | P12: 310 | Q12: =P12*0.158987 -> 49.28597 | R12: Capacity held fixed over the projection period.
A13: 2016 | B13: 4.1073528 | C13: 3.5353961 | D13: 3.5353961 | E13: 3.5353961 | F13: Million barrels per day (MMb/d) | O13: Milk River | P13: 97 | Q13: =P13*0.158987 -> 15.421739 | R13: Capacity held fixed over the projection period.
A14: 2017 | B14: 4.2071355 | C14: 3.82683 | D14: 3.82683 | E14: 3.82683 | F14: Million barrels per day (MMb/d) | O14: Aurora/Rangeland | P14: 44 | Q14: =P14*0.158987 -> 6.995428 | R14: Capacity held fixed over the projection period.
A15: 2018 | B15: 4.1833888 | C15: 4.1972218 | D15: 4.1972218 | E15: 4.1972218 | F15: Million barrels per day (MMb/d) | P15: =SUM(P8:P14) -> 5221 | Q15: =SUM(Q8:Q14) -> 830.07113
A16: 2019 | B16: 4.2494234 | C16: 4.2076526 | D16: 4.2076526 | E16: 4.2076526 | F16: Million barrels per day (MMb/d)
A17: 2020 | B17: 4.398062 | C17: 3.9309825 | D17: 3.9309825 | E17: 3.9309825 | F17: Million barrels per day (MMb/d)
A18: 2021 | B18: 4.5189718 | C18: 4.1948456 | D18: 4.1948456 | E18: 4.1948456 | F18: Million barrels per day (MMb/d)
A19: 2022 | B19: 4.80884 | C19: 4.3847824 | D19: 4.3847824 | E19: 4.3847824 | F19: Million barrels per day (MMb/d)
A20: 2023 | B20: 4.7560724 | C20: 4.6071818 | D20: 4.6071818 | E20: 4.6071818 | F20: Million barrels per day (MMb/d)
A21: 2024 | B21: 5.1992299 | C21: 4.7528306 | D21: 4.7528306 | E21: 4.7528306 | F21: Million barrels per day (MMb/d)
A22: 2025 | B22: 5.3408966 | C22: 4.8796684 | D22: 4.8265824 | E22: 4.8754725 | F22: Million barrels per day (MMb/d)
A23: 2026 | B23: 5.3408966 | C23: 4.9525048 | D23: 4.8732869 | E23: 4.9375225 | F23: Million barrels per day (MMb/d) | P23: 2009 | Q23: 353 | R23: =Q23*0.158987 -> 56.122411
A24: 2027 | B24: 5.3408966 | C24: 4.9830637 | D24: 4.9072772 | E24: 5.0526354 | F24: Million barrels per day (MMb/d) | O24: 4 | P24: 2010 | Q24: 397 | R24: =Q24*0.158987 -> 63.117839
A25: 2028 | B25: 5.3408966 | C25: 5.0220256 | D25: 4.8675317 | E25: 5.1184595 | F25: Million barrels per day (MMb/d) | O25: 5 | P25: 2011 | Q25: 397 | R25: =Q25*0.158987 -> 63.117839
A26: 2029 | B26: 5.3408966 | C26: 5.0417036 | D26: 4.8636988 | E26: 5.1704694 | F26: Million barrels per day (MMb/d) | O26: 6 | P26: 2012 | Q26: 397 | R26: =Q26*0.158987 -> 63.117839
A27: 2030 | B27: 5.3408966 | C27: 5.0606036 | D27: 4.8108068 | E27: 5.1563353 | F27: Million barrels per day (MMb/d) | O27: 7 | P27: 2013 | Q27: 397 | R27: =Q27*0.158987 -> 63.117839
A28: 2031 | B28: 5.3408966 | C28: 5.0640541 | D28: 4.6411568 | E28: 5.1328142 | F28: Million barrels per day (MMb/d) | O28: 8 | P28: 2014 | Q28: 416 | R28: =Q28*0.158987 -> 66.138592
A29: 2032 | B29: 5.3408966 | C29: 5.0734796 | D29: 4.4648753 | E29: 5.1600422 | F29: Million barrels per day (MMb/d) | O29: 9 | P29: 2015 | Q29: 453 | R29: =Q29*0.158987 -> 72.021111
A30: 2033 | B30: 5.3408966 | C30: 5.1503607 | D30: 4.1760919 | E30: 5.1235907 | F30: Million barrels per day (MMb/d) | O30: 10 | P30: 2016 | Q30: 453 | R30: =Q30*0.158987 -> 72.021111
A31: 2034 | B31: 5.3408966 | C31: 5.204792 | D31: 3.8986389 | E31: 5.0947573 | F31: Million barrels per day (MMb/d) | O31: 11 | P31: 2017 | Q31: 453 | R31: =Q31*0.158987 -> 72.021111
A32: 2035 | B32: 5.3408966 | C32: 5.1988547 | D32: 3.539836 | E32: 5.0675521 | F32: Million barrels per day (MMb/d) | O32: 12 | P32: 2018 | Q32: 453 | R32: =Q32*0.158987 -> 72.021111
A33: 2036 | B33: 5.3408966 | C33: 5.1578524 | D33: 3.218454 | E33: 4.961785 | F33: Million barrels per day (MMb/d) | O33: 13 | P33: 2019 | Q33: 460 | R33: =Q33*0.158987 -> 73.13402
A34: 2037 | B34: 5.3408966 | C34: 5.1107752 | D34: 2.8773005 | E34: 4.8531061 | F34: Million barrels per day (MMb/d) | O34: 14 | P34: 2020 | Q34: 460 | R34: =Q34*0.158987 -> 73.13402
A35: 2038 | B35: 5.3408966 | C35: 5.0685391 | D35: 2.5838993 | E35: 4.7336997 | F35: Million barrels per day (MMb/d) | O35: 15 | P35: 2021 | Q35: 512 | R35: =Q35*0.158987 -> 81.401344
... A39: 2042 | B39: 5.3408966 | C39: 4.9105287 | D39: 1.9182388 | E39: 4.2051746 | F39: Million barrels per day (MMb/d) | O39: 19 | P39: 2025 | Q39: 512 | R39: =Q39*0.158987 -> 81.401344
A40: 2043 | B40: 5.3408966 | C40: 4.8460966 | D40: 1.761538 | E40: 4.0910633 | F40: Million barrels per day (MMb/d)
